Workbook

Sheet Inicio
B1: SISTEMA CONTABLE MULTI-CLIENTE — MYPE Chile
B2: Normativa: NIIF Pymes (BT N°82) · LIR D.L. 824 · D.L. 825 IVA · Sin Macros
B4: ¿CÓMO EMPEZAR? — Siga estos pasos en orden
B5: 1️⃣ | C5: → Clientes | D5: Registre sus clientes (RUT, razón social, giro). Use la hoja 'Nuevo Cliente' como formulario.
B6: 2️⃣ | C6: → Cuentas | D6: Revise el Plan de Cuentas. Ya viene precargado con ~95 cuentas estándar por cliente.
B7: 3️⃣ | C7: → Libro Diario | D7: Ingrese los asientos contables día a día. Cada asiento debe cuadrar (Debe = Haber).
B8: 4️⃣ | C8: → Libro Mayor | D8: Consulte los saldos por cuenta. Se calculan automáticamente desde el Libro Diario.
B9: 5️⃣ | C9: → Balance General | D9: Revise el Estado de Situación Financiera. Se genera automáticamente.
B10: 6️⃣ | C10: → Estado Resultados | D10: Revise las utilidades o pérdidas del período. Se genera automáticamente.
B11: 7️⃣ | C11: → Indicadores | D11: Consulte los KPIs financieros con semáforos (liquidez, deuda, rentabilidad).
B12: 8️⃣ | C12: → Flujo de Caja | D12: Analice la salud de caja: runway, burn rate, punto de equilibrio.
B14: CONSEJOS IMPORTANTES
B15: 💡 | C15: Las celdas con fondo AMARILLO son editables. Las demás se calculan automáticamente — no las modifique.
B16: 💡 | C16: Cada asiento en el Libro Diario DEBE cuadrar: la suma del Debe = suma del Haber (partida doble).
B17: 💡 | C17: Use los filtros de Cliente y Año en la parte superior de cada hoja para cambiar la vista.
B18: 💡 | C18: Los indicadores con 🟢🟡🔴 se comparan contra benchmarks SERCOTEC/CMF para MYPE chilenas.
B19: 💡 | C19: Para auditar el archivo, pídale a Claude: 'audita la contabilidad' o 'revisa el programa contable'.
B21: Sistema contable para MYPE Chile — NIIF Pymes · LIR · D.L. 825 IVA · Ley 20.720 · CMF · SERCOTEC · CORFO — v2.0 (2025)
B23: AUTORES
B24: Sandro A. Gómez Araya | C24: Software Craftsman | D24: furiolabs.cl
B25: Danilo J. Gómez Araya | C25: Contador Auditor
B26: Este proyecto es parte de las iniciativas de experimentación e innovación de furiolabs.cl
B28: ADVERTENCIA LEGAL
B29: Este template es una herramienta de apoyo para la gestión contable interna. No reemplaza la asesoría de un contador público autorizado ni la revisión por un auditor independiente. Las tasas de impuesto y referencias normativas están actualizadas a marzo de 2026 y deben verificarse ante cambios legislativos.
B30: El usuario es responsable de la correcta aplicación de la normativa tributaria a su situación particular. Para declaraciones al SII (F-29, F-22, etc.), los formularios deben completarse en sii.cl. El uso de este template no genera responsabilidad alguna para sus autores.

Sheet Marco Regulatorio
A1: MARCO REGULATORIO Y PRÁCTICAS CONTABLES
A2: Documento de referencia: normativa vigente aplicada en este sistema contable para MYPE Chile.
A4: 1. NORMA CONTABLE: NIIF para Pymes (IFRS for SMEs)
A5: Obligatoria en Chile desde 2013 para entidades sin obligación pública de rendir cuentas (Boletín Técnico N°82, Colegio de Contadores A.G.). La 3ª edición de NIIF Pymes es aplicable desde el 1 de enero de 2027 (IASB 2024).
A7: Nº | B7: Sección NIIF | C7: Tema | D7: Aplicación en este sistema | E7: Hoja(s) afectada(s) | F7: Notas
A8: 1 | B8: Sec. 2 | C8: Conceptos fundamentales | D8: Base de devengo (no caja); la partida doble rige todo el Libro Diario | E8: Libro Diario | F8: Cada asiento debe cuadrar: ΣDebe = ΣHaber
A9: 2 | B9: Sec. 3 | C9: Presentación de EEFF | D9: Sistema genera 4 EEFF: Balance, EERR, Flujo de Caja, + Indicadores | E9: Todas | F9: Falta hoja de Notas a los EEFF (recomendable para presentación formal)
A10: 3 | B10: Sec. 4 | C10: Estado de Situación Financiera | D10: Balance clasifica Corriente / No Corriente (plazo 12 meses) | E10: Balance General | F10: Activos: 1xxx / Pasivos: 2xxx / Patrimonio: 23xx
A11: 4 | B11: Sec. 5 | C11: Estado de Resultado Integral | D11: Formato por función del gasto con ingresos, costos y gastos operacionales | E11: Estado Resultados | F11: Incluye Margen Bruto, EBITDA, Resultado antes de impuesto
A12: 5 | B12: Sec. 7 | C12: Estado de Flujos de Efectivo | D12: Método indirecto, 3 secciones: Operación, Inversión, Financiamiento | E12: Flujo de Caja | F12: Cumple NIC 7 / NIIF Pymes Sec. 7
A13: 6 | B13: Sec. 10 | C13: Políticas Contables | D13: Consistencia: mismas fórmulas SUMPRODUCT aplicadas uniformemente | E13: Todas | F13: Las fórmulas no cambian entre períodos ni clientes
A14: 7 | B14: Sec. 17 | C14: Propiedad, Planta y Equipo | D14: Costo histórico menos depreciación acumulada; cuentas reguladoras 12xxxxx | E14: Balance General, Cuentas | F14: Depreciación acumulada = cuenta con saldo acreedor dentro de Activo
A15: 8 | B15: Sec. 22 | C15: Patrimonio | D15: Capital (2301001), Resultado del Ejercicio (2302001), Resultados Acumulados (2302101) | E15: Balance General | F15: Aportes de capital no constituyen renta (Art. 17 N°5 LIR)
A16: 9 | B16: Sec. 23 | C16: Ingresos | D16: Reconocimiento cuando es probable y medible; cuentas 4xxx | E16: Estado Resultados | F16: Ventas de bienes (4101001), servicios (4101002)
A17: 10 | B17: Sec. 27 | C17: Deterioro del Valor | D17: No automatizado en este template; requiere evaluación manual al cierre | E17: — | F17: Verificar indicadores de deterioro en Activos Fijos
A18: 11 | B18: Sec. 28 | C18: Beneficios a Empleados | D18: Provisión Vacaciones (2104001) incluida en plan de cuentas | E18: Cuentas, Balance | F18: Art. 67 Código del Trabajo; evaluar también IAS (Art. 163)
A19: 12 | B19: Sec. 29 | C19: Impuesto a las Ganancias | D19: Impuesto 1ª Categoría calculado en Estado de Resultados | E19: Estado Resultados | F19: Régimen Pro-Pyme 25% o General 27% (ver sección tributaria)
A21: 2. LEGISLACIÓN TRIBUTARIA CHILENA
A23: 2.1 Ley de la Renta (D.L. 824 / LIR)
A24: Nº | B24: Artículo | C24: Tema | D24: Aplicación en este sistema | E24: Hoja(s) afectada(s) | F24: Notas
A25: 1 | B25: Art. 14D | C25: Régimen Pro-Pyme | D25: Tasa de impuesto 12,5% Pro-Pyme 2025-2027 (Ley 21.755), 15% en 2028, 25% normal; o 27% General. El EERR calcula según régimen del cliente | E25: Estado Resultados | F25: Ingresos ≤ 75.000 UF anuales → Pro-Pyme. Ley 21.755: tasa 12,5% (2025-2027)
A26: 2 | B26: Art. 17 N°5 | C26: Aportes de capital | D26: No constituyen renta; se registran como Capital (2301001), no como ingreso | E26: Libro Diario, Balance | F26: Asiento: Debe Caja/Bancos — Haber Capital
A27: 3 | B27: Art. 29-33 | C27: Base imponible (RLI) | D27: EERR llega a Resultado antes de Impuesto; se aplican agregados/deducciones Art. 33 | E27: Estado Resultados | F27: Gastos rechazados se agregan a la RLI
A28: 4 | B28: Art. 31 N°1-7 | C28: Gastos deducibles | D28: Gastos registrados en cuentas 3xxx deben cumplir requisitos de deducibilidad | E28: Libro Diario, EERR | F28: Pagados, necesarios para el giro, acreditados
A29: 5 | B29: Art. 31 N°5 | C29: Depreciación normal | D29: Tablas SII (Res. Ex. N°43/2002); vida útil según tipo de activo | E29: Balance General | F29: Depreciación acelerada = 1/3 de vida útil normal
A30: 6 | B30: Art. 31 N°5 bis | C30: Depreciación instantánea | D30: 100% en un ejercicio para bienes nuevos adquiridos por Pro-Pyme (Ley 21.210) | E30: Balance General | F30: Solo aplica régimen Pro-Pyme (Art. 14D)
A31: 7 | B31: Art. 41 | C31: Corrección monetaria | D31: No implementada automáticamente; requiere ajuste manual de cierre | E31: — | F31: Actualización por IPC de activos y pasivos
A32: 8 | B32: Art. 42 N°2 | C32: Retención honorarios | D32: Tasa 2024: 13,75% (Ley 21.133 transitorio); sube a 17% en 2028 | E32: Estado Resultados | F32: Nota en celda de Asesorías y Honorarios
A33: 9 | B33: Art. 84 | C33: PPM | D33: Cuenta PPM (1107201) en plan de cuentas; se compensa contra impuesto anual | E33: Balance General, Cuentas | F33: Pagos provisionales mensuales
A35: 2.2 Impuesto al Valor Agregado (D.L. 825)
A36: Nº | B36: Artículo | C36: Tema | D36: Aplicación en este sistema | E36: Hoja(s) afectada(s) | F36: Notas
A37: 1 | B37: Art. 8 | C37: Hecho gravado | D37: Ventas y servicios afectos se registran en cuentas 4xxx con IVA separado | E37: Libro Diario | F37: IVA = 19% sobre base imponible
A38: 2 | B38: Art. 14 | C38: Tasa vigente: 19% | D38: Cálculos de IVA en el sistema usan 19% como tasa fija | E38: Libro Diario | F38: Vigente 2024-2025
A39: 3 | B39: Art. 23 | C39: Crédito Fiscal | D39: Cuenta 1107101 (IVA Crédito Fiscal) registra IVA pagado en compras | E39: Cuentas, Libro Diario | F39: Activo Corriente; se compensa contra Débito Fiscal
A40: 4 | B40: Art. 24 | C40: Débito Fiscal | D40: Cuenta 2105101 (IVA Débito Fiscal) registra IVA cobrado en ventas | E40: Cuentas, Libro Diario | F40: Pasivo Corriente; se paga en F-29 mensual
A42: 2.3 Legislación Laboral (Código del Trabajo)
A43: Nº | B43: Artículo | C43: Tema | D43: Aplicación en este sistema | E43: Hoja(s) afectada(s) | F43: Notas
A44: 1 | B44: Art. 44 | C44: Remuneración mínima | D44: Gasto remuneraciones (3103001); referencia: $500.000 (2025) | E44: Libro Diario, EERR | F44: Verificar monto vigente cada año
A45: 2 | B45: Art. 67 | C45: Feriado anual (vacaciones) | D45: Provisión Vacaciones (2104001) en plan de cuentas; pasivo corriente | E45: Cuentas, Balance | F45: Derecho irrenunciable; NIIF Pymes Sec. 28
A46: 3 | B46: Art. 163 | C46: Indemnización por años | D46: Cuenta 2104002 (Provisión IAS) disponible si la empresa tiene política de pago | E46: Cuentas | F46: No obligatoria salvo política interna de la empresa
...

Sheet Clientes
A1: REGISTRO DE CLIENTES
A2: 📝 Ingrese un cliente por fila. El ID (ej: CLI001) se usa en todas las demás hojas. Use la hoja 'Nuevo Cliente' como formulario de ingreso, o escriba directamente aquí.
A3: ID Cliente | B3: RUT | C3: Razón Social | D3: Giro | E3: Domicilio | F3: Comuna | G3: Representante Legal | H3: RUT Rep.Legal | I3: Teléfono | J3: E-mail
A4: CLI001 | B4: 76.000.000-0 | C4: ← Ingrese aquí su primer cliente

Sheet Nuevo Cliente
A1: FORMULARIO DE REGISTRO DE CLIENTE
A3: 📝 Complete los campos amarillos y luego copie la fila de Vista Previa (fila 20) a la hoja CLIENTES. Los campos con borde amarillo son editables.
A5: ID Cliente | F5: Ej: CLI004 — identificador único
A6: RUT | F6: Formato: 76.543.210-K
A7: Razón Social | F7: Nombre legal de la empresa
A8: Giro | F8: Actividad económica principal
A9: Domicilio | F9: Calle, número
A10: Comuna
A11: Representante Legal | F11: Nombre completo
A12: RUT Rep. Legal | F12: Formato: 12.345.678-9
A13: Teléfono | F13: Ej: (56-2) 2345 6789
A14: E-mail | F14: Correo de contacto
A16: ▶ Para agregar: copie la fila de datos ingresados y péguela en la hoja CLIENTES
A18: VISTA PREVIA — Fila a copiar en hoja CLIENTES
A19: ID Cliente | B19: RUT | C19: Razón Social | D19: Giro | E19: Domicilio | F19: Comuna
A20: =C5 -> 0 | B20: =C6 -> 0 | C20: =C7 -> 0 | D20: =C8 -> 0 | E20: =C9 -> 0 | F20: =C10 -> 0

Sheet Cuentas
A1: PLAN DE CUENTAS — MULTI-CLIENTE
A2: 📝 Cada cliente tiene su propio plan de cuentas (~95 cuentas estándar PCGA Chile). Puede agregar cuentas nuevas usando el formulario de la fila 4, o directamente en la tabla. Los códigos siguen: 1xxx=Activo, 2xxx=Pasivo, 3xxx=Gasto, 4xxx=Ingreso.
A3: AGREGAR NUEVA CUENTA
A4: Cliente: | C4: Código: | E4: Nombre Cuenta: | G4: Tipo:
A5: ↑ Complete los campos y copie manualmente la fila de datos en la tabla inferior. El Código debe ser único por cliente.
A7: ID Cliente | B7: Código Cuenta | C7: Nombre Cuenta | D7: Tipo | E7: Cód. Tipo | F7: Subtipo/Clasificación | G7: Activo en Uso | H7: Notas
A8: CLI001 | B8: 1101001 | C8: Caja | D8: ACTIVO | E8: =IF(D8="ACTIVO",1,IF(D8="PASIVO",2,IF(D8="PERDIDA",3,IF(D8="GANANCIA",4,0)))) -> 1 | G8: Sí
A9: CLI001 | B9: 1101002 | C9: Bancos | D9: ACTIVO | E9: =IF(D9="ACTIVO",1,IF(D9="PASIVO",2,IF(D9="PERDIDA",3,IF(D9="GANANCIA",4,0)))) -> 1 | G9: Sí
A10: CLI001 | B10: 1104001 | C10: Clientes Varios | D10: ACTIVO | E10: =IF(D10="ACTIVO",1,IF(D10="PASIVO",2,IF(D10="PERDIDA",3,IF(D10="GANANCIA",4,0)))) -> 1 | G10: Sí
A11: CLI001 | B11: 1106001 | C11: Retiros Acumulados-Ej. Anteriores. | D11: ACTIVO | E11: =IF(D11="ACTIVO",1,IF(D11="PASIVO",2,IF(D11="PERDIDA",3,IF(D11="GANANCIA",4,0)))) -> 1 | G11: Sí
A12: CLI001 | B12: 1106002 | C12: Cta. Cte. SOCIO | D12: ACTIVO | E12: =IF(D12="ACTIVO",1,IF(D12="PASIVO",2,IF(D12="PERDIDA",3,IF(D12="GANANCIA",4,0)))) -> 1 | G12: Sí
A13: CLI001 | B13: 1106003 | C13: Cta. Cte. SOCIO | D13: ACTIVO | E13: =IF(D13="ACTIVO",1,IF(D13="PASIVO",2,IF(D13="PERDIDA",3,IF(D13="GANANCIA",4,0)))) -> 1 | G13: Sí
A14: CLI001 | B14: 1106004 | C14: Cta. Cte. SOCIO | D14: ACTIVO | E14: =IF(D14="ACTIVO",1,IF(D14="PASIVO",2,IF(D14="PERDIDA",3,IF(D14="GANANCIA",4,0)))) -> 1 | G14: Sí
A15: CLI001 | B15: 1107001 | C15: Impuestos por Recuperar - Renta | D15: ACTIVO | E15: =IF(D15="ACTIVO",1,IF(D15="PASIVO",2,IF(D15="PERDIDA",3,IF(D15="GANANCIA",4,0)))) -> 1 | G15: Sí
A16: CLI001 | B16: 1107002 | C16: Impuestos por Recuperar - IVA | D16: ACTIVO | E16: =IF(D16="ACTIVO",1,IF(D16="PASIVO",2,IF(D16="PERDIDA",3,IF(D16="GANANCIA",4,0)))) -> 1 | G16: Sí
A17: CLI001 | B17: 1107003 | C17: Imposiciones por Recuperar | D17: ACTIVO | E17: =IF(D17="ACTIVO",1,IF(D17="PASIVO",2,IF(D17="PERDIDA",3,IF(D17="GANANCIA",4,0)))) -> 1 | G17: Sí
A18: CLI001 | B18: 1107101 | C18: IVA Crédito Fiscal 19% | D18: ACTIVO | E18: =IF(D18="ACTIVO",1,IF(D18="PASIVO",2,IF(D18="PERDIDA",3,IF(D18="GANANCIA",4,0)))) -> 1 | G18: Sí
A19: CLI001 | B19: 1107103 | C19: IVA Crédito Fiscal no Retenido 11% | D19: ACTIVO | E19: =IF(D19="ACTIVO",1,IF(D19="PASIVO",2,IF(D19="PERDIDA",3,IF(D19="GANANCIA",4,0)))) -> 1 | G19: Sí
... A292: CLI003 | B292: 4201102 | C292: Otros Ingresos | D292: GANANCIA | E292: =IF(D292="ACTIVO",1,IF(D292="PASIVO",2,IF(D292="PERDIDA",3,IF(D292="GANANCIA",4,0)))) -> 4 | G292: Sí
E293: =IF(D293="ACTIVO",1,IF(D293="PASIVO",2,IF(D293="PERDIDA",3,IF(D293="GANANCIA",4,0)))) -> 0
E294: =IF(D294="ACTIVO",1,IF(D294="PASIVO",2,IF(D294="PERDIDA",3,IF(D294="GANANCIA",4,0)))) -> 0
E295: =IF(D295="ACTIVO",1,IF(D295="PASIVO",2,IF(D295="PERDIDA",3,IF(D295="GANANCIA",4,0)))) -> 0
E296: =IF(D296="ACTIVO",1,IF(D296="PASIVO",2,IF(D296="PERDIDA",3,IF(D296="GANANCIA",4,0)))) -> 0
E297: =IF(D297="ACTIVO",1,IF(D297="PASIVO",2,IF(D297="PERDIDA",3,IF(D297="GANANCIA",4,0)))) -> 0
E298: =IF(D298="ACTIVO",1,IF(D298="PASIVO",2,IF(D298="PERDIDA",3,IF(D298="GANANCIA",4,0)))) -> 0
E299: =IF(D299="ACTIVO",1,IF(D299="PASIVO",2,IF(D299="PERDIDA",3,IF(D299="GANANCIA",4,0)))) -> 0
E300: =IF(D300="ACTIVO",1,IF(D300="PASIVO",2,IF(D300="PERDIDA",3,IF(D300="GANANCIA",4,0)))) -> 0
E301: =IF(D301="ACTIVO",1,IF(D301="PASIVO",2,IF(D301="PERDIDA",3,IF(D301="GANANCIA",4,0)))) -> 0
E302: =IF(D302="ACTIVO",1,IF(D302="PASIVO",2,IF(D302="PERDIDA",3,IF(D302="GANANCIA",4,0)))) -> 0
E303: =IF(D303="ACTIVO",1,IF(D303="PASIVO",2,IF(D303="PERDIDA",3,IF(D303="GANANCIA",4,0)))) -> 0
E304: =IF(D304="ACTIVO",1,IF(D304="PASIVO",2,IF(D304="PERDIDA",3,IF(D304="GANANCIA",4,0)))) -> 0
... E342: =IF(D342="ACTIVO",1,IF(D342="PASIVO",2,IF(D342="PERDIDA",3,IF(D342="GANANCIA",4,0)))) -> 0

Sheet Libro Diario
A1: LIBRO DIARIO — INGRESO DE ASIENTOS CONTABLES
A2: 📝 INSTRUCCIONES: (1) Seleccione Cliente en A5 (2) Ingrese Nº Asiento, Fecha, Código de Cuenta, Glosa, y montos en Debe o Haber (3) Cada asiento DEBE cuadrar: Σ Debe = Σ Haber (4) La fila 6 muestra si el asiento cuadra ✓ o no ✗
A3: INGRESAR NUEVO ASIENTO
A4: Cliente | B4: Nº Asiento | C4: Fecha | D4: Glosa General | E4: Cuenta (Cód.) | F4: Nombre Cuenta | G4: Detalle | H4: Debe (CLP) | I4: Haber (CLP) | J4: Tipo | K4: Sucursal
F5: =IFERROR(INDEX(Cuentas!$C$8:$C$500,MATCH(A5&"|"&E5,Cuentas!$A$8:$A$500&"|"&Cuentas!$B$8:$B$500,0)),"") -> 0
A6: TOTALES DEL ASIENTO INGRESADO → | H6: =SUMIF($A$10:$A$5000,A5,$H$10:$H$5000) -> 0 | I6: =SUMIF($A$10:$A$5000,A5,$I$10:$I$5000) -> 0 | J6: =IF(H6=I6,"✓ CUADRADO","✗ DESCUADRADO") -> ✓ CUADRADO
A8: FILTRO ACTIVO — Escriba un ID de cliente en B8 para filtrar (ej: CLI001), o "TODOS" para ver todos los asientos
A9: Cliente | B9: Nº Asiento | C9: Fecha | D9: Mes | E9: Código Cta. | F9: Nombre Cuenta | G9: Glosa / Detalle | H9: Debe (CLP) | I9: Haber (CLP) | J9: Tipo | K9: Sucursal
D10: =IF(C10="","",MONTH(C10)) | F10: =IFERROR(INDEX(Cuentas!$C$8:$C$500,MATCH(A10&"|"&E10,Cuentas!$A$8:$A$500&"|"&Cuentas!$B$8:$B$500,0)),"") -> 0 | G10: ← Ingrese su primer asiento aquí
D11: =IF(C11="","",MONTH(C11)) | F11: =IFERROR(INDEX(Cuentas!$C$8:$C$500,MATCH(A11&"|"&E11,Cuentas!$A$8:$A$500&"|"&Cuentas!$B$8:$B$500,0)),"") -> 0
D12: =IF(C12="","",MONTH(C12)) | F12: =IFERROR(INDEX(Cuentas!$C$8:$C$500,MATCH(A12&"|"&E12,Cuentas!$A$8:$A$500&"|"&Cuentas!$B$8:$B$500,0)),"") -> 0
D13: =IF(C13="","",MONTH(C13)) | F13: =IFERROR(INDEX(Cuentas!$C$8:$C$500,MATCH(A13&"|"&E13,Cuentas!$A$8:$A$500&"|"&Cuentas!$B$8:$B$500,0)),"") -> 0
D14: =IF(C14="","",MONTH(C14)) | F14: =IFERROR(INDEX(Cuentas!$C$8:$C$500,MATCH(A14&"|"&E14,Cuentas!$A$8:$A$500&"|"&Cuentas!$B$8:$B$500,0)),"") -> 0
D15: =IF(C15="","",MONTH(C15)) | F15: =IFERROR(INDEX(Cuentas!$C$8:$C$500,MATCH(A15&"|"&E15,Cuentas!$A$8:$A$500&"|"&Cuentas!$B$8:$B$500,0)),"") -> 0
D16: =IF(C16="","",MONTH(C16)) | F16: =IFERROR(INDEX(Cuentas!$C$8:$C$500,MATCH(A16&"|"&E16,Cuentas!$A$8:$A$500&"|"&Cuentas!$B$8:$B$500,0)),"") -> 0
D17: =IF(C17="","",MONTH(C17)) | F17: =IFERROR(INDEX(Cuentas!$C$8:$C$500,MATCH(A17&"|"&E17,Cuentas!$A$8:$A$500&"|"&Cuentas!$B$8:$B$500,0)),"") -> 0
D18: =IF(C18="","",MONTH(C18)) | F18: =IFERROR(INDEX(Cuentas!$C$8:$C$500,MATCH(A18&"|"&E18,Cuentas!$A$8:$A$500&"|"&Cuentas!$B$8:$B$500,0)),"") -> 0
D19: =IF(C19="","",MONTH(C19)) | F19: =IFERROR(INDEX(Cuentas!$C$8:$C$500,MATCH(A19&"|"&E19,Cuentas!$A$8:$A$500&"|"&Cuentas!$B$8:$B$500,0)),"") -> 0
D20: =IF(C20="","",MONTH(C20)) | F20: =IFERROR(INDEX(Cuentas!$C$8:$C$500,MATCH(A20&"|"&E20,Cuentas!$A$8:$A$500&"|"&Cuentas!$B$8:$B$500,0)),"") -> 0
D21: =IF(C21="","",MONTH(C21)) | F21: =IFERROR(INDEX(Cuentas!$C$8:$C$500,MATCH(A21&"|"&E21,Cuentas!$A$8:$A$500&"|"&Cuentas!$B$8:$B$500,0)),"") -> 0
D22: =IF(C22="","",MONTH(C22)) | F22: =IFERROR(INDEX(Cuentas!$C$8:$C$500,MATCH(A22&"|"&E22,Cuentas!$A$8:$A$500&"|"&Cuentas!$B$8:$B$500,0)),"") -> 0
... D517: =IF(C517="","",MONTH(C517)) | F517: =IFERROR(INDEX(Cuentas!$C$8:$C$500,MATCH(A517&"|"&E517,Cuentas!$A$8:$A$500&"|"&Cuentas!$B$8:$B$500,0)),"") -> 0

Sheet Libro Mayor
A1: LIBRO MAYOR — RESUMEN POR CUENTA
A2: 📊 Este resumen se calcula AUTOMÁTICAMENTE desde el Libro Diario. Cambie el Cliente y Año en los campos amarillos de arriba para consultar otro período. No modifique las celdas de datos — son fórmulas.
A3: FILTROS DE CONSULTA
A4: Cliente: | B4: CLI001 | D4: Período (Año): | E4: 2025 | F4: ← Escriba el ID de cliente y el año a consultar
A6: Código Cta. | B6: Nombre Cuenta | C6: Tipo | D6: Tratamiento | E6: Total Debe | F6: Total Haber | G6: Saldo Deudor | H6: Saldo Acreedor | I6: Saldo Final
A7: Las fórmulas calculan automáticamente desde Libro Diario filtrando por el Cliente y Período seleccionados arriba.
A8: 1101001 | B8: =IFERROR(INDEX(Cuentas!$C$8:$C$500,MATCH($B$4&"|"&A8,Cuentas!$A$8:$A$500&"|"&Cuentas!$B$8:$B$500,0)),"Caja") -> Caja | C8: =IFERROR(INDEX(Cuentas!$D$8:$D$500,MATCH($B$4&"|"&A8,Cuentas!$A$8:$A$500&"|"&Cuentas!$B$8:$B$500,0)),"ACTIVO") -> ACTIVO | D8: =IF(OR(C8="ACTIVO",C8="PERDIDA"),"Deudor","Acreedor") -> Deudor | E8: =SUMPRODUCT(('Libro Diario'!$A$10:$A$5000=$B$4)*('Libro Diario'!$E$10:$E$5000=A8)*(YEAR('Libro Diario'!$C$10:$C$5000)=$E$4)*('Libro Diario'!$H$10:$H$5000)) -> 0 | F8: =SUMPRODUCT(('Libro Diario'!$A$10:$A$5000=$B$4)*('Libro Diario'!$E$10:$E$5000=A8)*(YEAR('Libro Diario'!$C$10:$C$5000)=$E$4)*('Libro Diario'!$I$10:$I$5000)) -> 0 | G8: =IF(E8>F8,E8-F8,"") | H8: =IF(F8>E8,F8-E8,"") | I8: =IF(OR(C8="ACTIVO",C8="PERDIDA"),E8-F8,F8-E8) -> 0
A9: 1101002 | B9: =IFERROR(INDEX(Cuentas!$C$8:$C$500,MATCH($B$4&"|"&A9,Cuentas!$A$8:$A$500&"|"&Cuentas!$B$8:$B$500,0)),"Bancos") -> Bancos | C9: =IFERROR(INDEX(Cuentas!$D$8:$D$500,MATCH($B$4&"|"&A9,Cuentas!$A$8:$A$500&"|"&Cuentas!$B$8:$B$500,0)),"ACTIVO") -> ACTIVO | D9: =IF(OR(C9="ACTIVO",C9="PERDIDA"),"Deudor","Acreedor") -> Deudor | E9: =SUMPRODUCT(('Libro Diario'!$A$10:$A$5000=$B$4)*('Libro Diario'!$E$10:$E$5000=A9)*(YEAR('Libro Diario'!$C$10:$C$5000)=$E$4)*('Libro Diario'!$H$10:$H$5000)) -> 0 | F9: =SUMPRODUCT(('Libro Diario'!$A$10:$A$5000=$B$4)*('Libro Diario'!$E$10:$E$5000=A9)*(YEAR('Libro Diario'!$C$10:$C$5000)=$E$4)*('Libro Diario'!$I$10:$I$5000)) -> 0 | G9: =IF(E9>F9,E9-F9,"") | H9: =IF(F9>E9,F9-E9,"") | I9: =IF(OR(C9="ACTIVO",C9="PERDIDA"),E9-F9,F9-E9) -> 0
A10: 1104001 | B10: =IFERROR(INDEX(Cuentas!$C$8:$C$500,MATCH($B$4&"|"&A10,Cuentas!$A$8:$A$500&"|"&Cuentas!$B$8:$B$500,0)),"Clientes Varios") -> Clientes Varios | C10: =IFERROR(INDEX(Cuentas!$D$8:$D$500,MATCH($B$4&"|"&A10,Cuentas!$A$8:$A$500&"|"&Cuentas!$B$8:$B$500,0)),"ACTIVO") -> ACTIVO | D10: =IF(OR(C10="ACTIVO",C10="PERDIDA"),"Deudor","Acreedor") -> Deudor | E10: =SUMPRODUCT(('Libro Diario'!$A$10:$A$5000=$B$4)*('Libro Diario'!$E$10:$E$5000=A10)*(YEAR('Libro Diario'!$C$10:$C$5000)=$E$4)*('Libro Diario'!$H$10:$H$5000)) -> 0 | F10: =SUMPRODUCT(('Libro Diario'!$A$10:$A$5000=$B$4)*('Libro Diario'!$E$10:$E$5000=A10)*(YEAR('Libro Diario'!$C$10:$C$5000)=$E$4)*('Libro Diario'!$I$10:$I$5000)) -> 0 | G10: =IF(E10>F10,E10-F10,"") | H10: =IF(F10>E10,F10-E10,"") | I10: =IF(OR(C10="ACTIVO",C10="PERDIDA"),E10-F10,F10-E10) -> 0
A11: 1106001 | B11: =IFERROR(INDEX(Cuentas!$C$8:$C$500,MATCH($B$4&"|"&A11,Cuentas!$A$8:$A$500&"|"&Cuentas!$B$8:$B$500,0)),"Retiros Acumulados-Ej. Anteriores.") -> Retiros Acumulados-Ej. Anteriores. | C11: =IFERROR(INDEX(Cuentas!$D$8:$D$500,MATCH($B$4&"|"&A11,Cuentas!$A$8:$A$500&"|"&Cuentas!$B$8:$B$500,0)),"ACTIVO") -> ACTIVO | D11: =IF(OR(C11="ACTIVO",C11="PERDIDA"),"Deudor","Acreedor") -> Deudor | E11: =SUMPRODUCT(('Libro Diario'!$A$10:$A$5000=$B$4)*('Libro Diario'!$E$10:$E$5000=A11)*(YEAR('Libro Diario'!$C$10:$C$5000)=$E$4)*('Libro Diario'!$H$10:$H$5000)) -> 0 | F11: =SUMPRODUCT(('Libro Diario'!$A$10:$A$5000=$B$4)*('Libro Diario'!$E$10:$E$5000=A11)*(YEAR('Libro Diario'!$C$10:$C$5000)=$E$4)*('Libro Diario'!$I$10:$I$5000)) -> 0 | G11: =IF(E11>F11,E11-F11,"") | H11: =IF(F11>E11,F11-E11,"") | I11: =IF(OR(C11="ACTIVO",C11="PERDIDA"),E11-F11,F11-E11) -> 0
A12: 1106002 | B12: =IFERROR(INDEX(Cuentas!$C$8:$C$500,MATCH($B$4&"|"&A12,Cuentas!$A$8:$A$500&"|"&Cuentas!$B$8:$B$500,0)),"Cta. Cte. SOCIO") -> Cta. Cte. SOCIO | C12: =IFERROR(INDEX(Cuentas!$D$8:$D$500,MATCH($B$4&"|"&A12,Cuentas!$A$8:$A$500&"|"&Cuentas!$B$8:$B$500,0)),"ACTIVO") -> ACTIVO | D12: =IF(OR(C12="ACTIVO",C12="PERDIDA"),"Deudor","Acreedor") -> Deudor | E12: =SUMPRODUCT(('Libro Diario'!$A$10:$A$5000=$B$4)*('Libro Diario'!$E$10:$E$5000=A12)*(YEAR('Libro Diario'!$C$10:$C$5000)=$E$4)*('Libro Diario'!$H$10:$H$5000)) -> 0 | F12: =SUMPRODUCT(('Libro Diario'!$A$10:$A$5000=$B$4)*('Libro Diario'!$E$10:$E$5000=A12)*(YEAR('Libro Diario'!$C$10:$C$5000)=$E$4)*('Libro Diario'!$I$10:$I$5000)) -> 0 | G12: =IF(E12>F12,E12-F12,"") | H12: =IF(F12>E12,F12-E12,"") | I12: =IF(OR(C12="ACTIVO",C12="PERDIDA"),E12-F12,F12-E12) -> 0
A13: 1106003 | B13: =IFERROR(INDEX(Cuentas!$C$8:$C$500,MATCH($B$4&"|"&A13,Cuentas!$A$8:$A$500&"|"&Cuentas!$B$8:$B$500,0)),"Cta. Cte. SOCIO") -> Cta. Cte. SOCIO | C13: =IFERROR(INDEX(Cuentas!$D$8:$D$500,MATCH($B$4&"|"&A13,Cuentas!$A$8:$A$500&"|"&Cuentas!$B$8:$B$500,0)),"ACTIVO") -> ACTIVO | D13: =IF(OR(C13="ACTIVO",C13="PERDIDA"),"Deudor","Acreedor") -> Deudor | E13: =SUMPRODUCT(('Libro Diario'!$A$10:$A$5000=$B$4)*('Libro Diario'!$E$10:$E$5000=A13)*(YEAR('Libro Diario'!$C$10:$C$5000)=$E$4)*('Libro Diario'!$H$10:$H$5000)) -> 0 | F13: =SUMPRODUCT(('Libro Diario'!$A$10:$A$5000=$B$4)*('Libro Diario'!$E$10:$E$5000=A13)*(YEAR('Libro Diario'!$C$10:$C$5000)=$E$4)*('Libro Diario'!$I$10:$I$5000)) -> 0 | G13: =IF(E13>F13,E13-F13,"") | H13: =IF(F13>E13,F13-E13,"") | I13: =IF(OR(C13="ACTIVO",C13="PERDIDA"),E13-F13,F13-E13) -> 0
A14: 1106004 | B14: =IFERROR(INDEX(Cuentas!$C$8:$C$500,MATCH($B$4&"|"&A14,Cuentas!$A$8:$A$500&"|"&Cuentas!$B$8:$B$500,0)),"Cta. Cte. SOCIO") -> Cta. Cte. SOCIO | C14: =IFERROR(INDEX(Cuentas!$D$8:$D$500,MATCH($B$4&"|"&A14,Cuentas!$A$8:$A$500&"|"&Cuentas!$B$8:$B$500,0)),"ACTIVO") -> ACTIVO | D14: =IF(OR(C14="ACTIVO",C14="PERDIDA"),"Deudor","Acreedor") -> Deudor | E14: =SUMPRODUCT(('Libro Diario'!$A$10:$A$5000=$B$4)*('Libro Diario'!$E$10:$E$5000=A14)*(YEAR('Libro Diario'!$C$10:$C$5000)=$E$4)*('Libro Diario'!$H$10:$H$5000)) -> 0 | F14: =SUMPRODUCT(('Libro Diario'!$A$10:$A$5000=$B$4)*('Libro Diario'!$E$10:$E$5000=A14)*(YEAR('Libro Diario'!$C$10:$C$5000)=$E$4)*('Libro Diario'!$I$10:$I$5000)) -> 0 | G14: =IF(E14>F14,E14-F14,"") | H14: =IF(F14>E14,F14-E14,"") | I14: =IF(OR(C14="ACTIVO",C14="PERDIDA"),E14-F14,F14-E14) -> 0
A15: 1107001 | B15: =IFERROR(INDEX(Cuentas!$C$8:$C$500,MATCH($B$4&"|"&A15,Cuentas!$A$8:$A$500&"|"&Cuentas!$B$8:$B$500,0)),"Impuestos por Recuperar - Renta") -> Impuestos por Recuperar - Renta | C15: =IFERROR(INDEX(Cuentas!$D$8:$D$500,MATCH($B$4&"|"&A15,Cuentas!$A$8:$A$500&"|"&Cuentas!$B$8:$B$500,0)),"ACTIVO") -> ACTIVO | D15: =IF(OR(C15="ACTIVO",C15="PERDIDA"),"Deudor","Acreedor") -> Deudor | E15: =SUMPRODUCT(('Libro Diario'!$A$10:$A$5000=$B$4)*('Libro Diario'!$E$10:$E$5000=A15)*(YEAR('Libro Diario'!$C$10:$C$5000)=$E$4)*('Libro Diario'!$H$10:$H$5000)) -> 0 | F15: =SUMPRODUCT(('Libro Diario'!$A$10:$A$5000=$B$4)*('Libro Diario'!$E$10:$E$5000=A15)*(YEAR('Libro Diario'!$C$10:$C$5000)=$E$4)*('Libro Diario'!$I$10:$I$5000)) -> 0 | G15: =IF(E15>F15,E15-F15,"") | H15: =IF(F15>E15,F15-E15,"") | I15: =IF(OR(C15="ACTIVO",C15="PERDIDA"),E15-F15,F15-E15) -> 0
A16: 1107002 | B16: =IFERROR(INDEX(Cuentas!$C$8:$C$500,MATCH($B$4&"|"&A16,Cuentas!$A$8:$A$500&"|"&Cuentas!$B$8:$B$500,0)),"Impuestos por Recuperar - IVA") -> Impuestos por Recuperar - IVA | C16: =IFERROR(INDEX(Cuentas!$D$8:$D$500,MATCH($B$4&"|"&A16,Cuentas!$A$8:$A$500&"|"&Cuentas!$B$8:$B$500,0)),"ACTIVO") -> ACTIVO | D16: =IF(OR(C16="ACTIVO",C16="PERDIDA"),"Deudor","Acreedor") -> Deudor | E16: =SUMPRODUCT(('Libro Diario'!$A$10:$A$5000=$B$4)*('Libro Diario'!$E$10:$E$5000=A16)*(YEAR('Libro Diario'!$C$10:$C$5000)=$E$4)*('Libro Diario'!$H$10:$H$5000)) -> 0 | F16: =SUMPRODUCT(('Libro Diario'!$A$10:$A$5000=$B$4)*('Libro Diario'!$E$10:$E$5000=A16)*(YEAR('Libro Diario'!$C$10:$C$5000)=$E$4)*('Libro Diario'!$I$10:$I$5000)) -> 0 | G16: =IF(E16>F16,E16-F16,"") | H16: =IF(F16>E16,F16-E16,"") | I16: =IF(OR(C16="ACTIVO",C16="PERDIDA"),E16-F16,F16-E16) -> 0
A17: 1107003 | B17: =IFERROR(INDEX(Cuentas!$C$8:$C$500,MATCH($B$4&"|"&A17,Cuentas!$A$8:$A$500&"|"&Cuentas!$B$8:$B$500,0)),"Imposiciones por Recuperar") -> Imposiciones por Recuperar | C17: =IFERROR(INDEX(Cuentas!$D$8:$D$500,MATCH($B$4&"|"&A17,Cuentas!$A$8:$A$500&"|"&Cuentas!$B$8:$B$500,0)),"ACTIVO") -> ACTIVO | D17: =IF(OR(C17="ACTIVO",C17="PERDIDA"),"Deudor","Acreedor") -> Deudor | E17: =SUMPRODUCT(('Libro Diario'!$A$10:$A$5000=$B$4)*('Libro Diario'!$E$10:$E$5000=A17)*(YEAR('Libro Diario'!$C$10:$C$5000)=$E$4)*('Libro Diario'!$H$10:$H$5000)) -> 0 | F17: =SUMPRODUCT(('Libro Diario'!$A$10:$A$5000=$B$4)*('Libro Diario'!$E$10:$E$5000=A17)*(YEAR('Libro Diario'!$C$10:$C$5000)=$E$4)*('Libro Diario'!$I$10:$I$5000)) -> 0 | G17: =IF(E17>F17,E17-F17,"") | H17: =IF(F17>E17,F17-E17,"") | I17: =IF(OR(C17="ACTIVO",C17="PERDIDA"),E17-F17,F17-E17) -> 0
A18: 1107101 | B18: =IFERROR(INDEX(Cuentas!$C$8:$C$500,MATCH($B$4&"|"&A18,Cuentas!$A$8:$A$500&"|"&Cuentas!$B$8:$B$500,0)),"IVA Crédito Fiscal 19%") -> IVA Crédito Fiscal 19% | C18: =IFERROR(INDEX(Cuentas!$D$8:$D$500,MATCH($B$4&"|"&A18,Cuentas!$A$8:$A$500&"|"&Cuentas!$B$8:$B$500,0)),"ACTIVO") -> ACTIVO | D18: =IF(OR(C18="ACTIVO",C18="PERDIDA"),"Deudor","Acreedor") -> Deudor | E18: =SUMPRODUCT(('Libro Diario'!$A$10:$A$5000=$B$4)*('Libro Diario'!$E$10:$E$5000=A18)*(YEAR('Libro Diario'!$C$10:$C$5000)=$E$4)*('Libro Diario'!$H$10:$H$5000)) -> 0 | F18: =SUMPRODUCT(('Libro Diario'!$A$10:$A$5000=$B$4)*('Libro Diario'!$E$10:$E$5000=A18)*(YEAR('Libro Diario'!$C$10:$C$5000)=$E$4)*('Libro Diario'!$I$10:$I$5000)) -> 0 | G18: =IF(E18>F18,E18-F18,"") | H18: =IF(F18>E18,F18-E18,"") | I18: =IF(OR(C18="ACTIVO",C18="PERDIDA"),E18-F18,F18-E18) -> 0
A19: 1107103 | B19: =IFERROR(INDEX(Cuentas!$C$8:$C$500,MATCH($B$4&"|"&A19,Cuentas!$A$8:$A$500&"|"&Cuentas!$B$8:$B$500,0)),"IVA Crédito Fiscal no Retenido 11%") -> IVA Crédito Fiscal no Retenido 11% | C19: =IFERROR(INDEX(Cuentas!$D$8:$D$500,MATCH($B$4&"|"&A19,Cuentas!$A$8:$A$500&"|"&Cuentas!$B$8:$B$500,0)),"ACTIVO") -> ACTIVO | D19: =IF(OR(C19="ACTIVO",C19="PERDIDA"),"Deudor","Acreedor") -> Deudor | E19: =SUMPRODUCT(('Libro Diario'!$A$10:$A$5000=$B$4)*('Libro Diario'!$E$10:$E$5000=A19)*(YEAR('Libro Diario'!$C$10:$C$5000)=$E$4)*('Libro Diario'!$H$10:$H$5000)) -> 0 | F19: =SUMPRODUCT(('Libro Diario'!$A$10:$A$5000=$B$4)*('Libro Diario'!$E$10:$E$5000=A19)*(YEAR('Libro Diario'!$C$10:$C$5000)=$E$4)*('Libro Diario'!$I$10:$I$5000)) -> 0 | G19: =IF(E19>F19,E19-F19,"") | H19: =IF(F19>E19,F19-E19,"") | I19: =IF(OR(C19="ACTIVO",C19="PERDIDA"),E19-F19,F19-E19) -> 0
A20: 1107201 | B20: =IFERROR(INDEX(Cuentas!$C$8:$C$500,MATCH($B$4&"|"&A20,Cuentas!$A$8:$A$500&"|"&Cuentas!$B$8:$B$500,0)),"P.P.M.") -> P.P.M. | C20: =IFERROR(INDEX(Cuentas!$D$8:$D$500,MATCH($B$4&"|"&A20,Cuentas!$A$8:$A$500&"|"&Cuentas!$B$8:$B$500,0)),"ACTIVO") -> ACTIVO | D20: =IF(OR(C20="ACTIVO",C20="PERDIDA"),"Deudor","Acreedor") -> Deudor | E20: =SUMPRODUCT(('Libro Diario'!$A$10:$A$5000=$B$4)*('Libro Diario'!$E$10:$E$5000=A20)*(YEAR('Libro Diario'!$C$10:$C$5000)=$E$4)*('Libro Diario'!$H$10:$H$5000)) -> 0 | F20: =SUMPRODUCT(('Libro Diario'!$A$10:$A$5000=$B$4)*('Libro Diario'!$E$10:$E$5000=A20)*(YEAR('Libro Diario'!$C$10:$C$5000)=$E$4)*('Libro Diario'!$I$10:$I$5000)) -> 0 | G20: =IF(E20>F20,E20-F20,"") | H20: =IF(F20>E20,F20-E20,"") | I20: =IF(OR(C20="ACTIVO",C20="PERDIDA"),E20-F20,F20-E20) -> 0
A21: 1107301 | B21: =IFERROR(INDEX(Cuentas!$C$8:$C$500,MATCH($B$4&"|"&A21,Cuentas!$A$8:$A$500&"|"&Cuentas!$B$8:$B$500,0)),"Credito Diessel Transporte Carga") -> Credito Diessel Transporte Carga | C21: =IFERROR(INDEX(Cuentas!$D$8:$D$500,MATCH($B$4&"|"&A21,Cuentas!$A$8:$A$500&"|"&Cuentas!$B$8:$B$500,0)),"ACTIVO") -> ACTIVO | D21: =IF(OR(C21="ACTIVO",C21="PERDIDA"),"Deudor","Acreedor") -> Deudor | E21: =SUMPRODUCT(('Libro Diario'!$A$10:$A$5000=$B$4)*('Libro Diario'!$E$10:$E$5000=A21)*(YEAR('Libro Diario'!$C$10:$C$5000)=$E$4)*('Libro Diario'!$H$10:$H$5000)) -> 0 | F21: =SUMPRODUCT(('Libro Diario'!$A$10:$A$5000=$B$4)*('Libro Diario'!$E$10:$E$5000=A21)*(YEAR('Libro Diario'!$C$10:$C$5000)=$E$4)*('Libro Diario'!$I$10:$I$5000)) -> 0 | G21: =IF(E21>F21,E21-F21,"") | H21: =IF(F21>E21,F21-E21,"") | I21: =IF(OR(C21="ACTIVO",C21="PERDIDA"),E21-F21,F21-E21) -> 0
A22: 1107302 | B22: =IFERROR(INDEX(Cuentas!$C$8:$C$500,MATCH($B$4&"|"&A22,Cuentas!$A$8:$A$500&"|"&Cuentas!$B$8:$B$500,0)),"Art. 33 bis (4%) Activo Fijo") -> Art. 33 bis (4%) Activo Fijo | C22: =IFERROR(INDEX(Cuentas!$D$8:$D$500,MATCH($B$4&"|"&A22,Cuentas!$A$8:$A$500&"|"&Cuentas!$B$8:$B$500,0)),"ACTIVO") -> ACTIVO | D22: =IF(OR(C22="ACTIVO",C22="PERDIDA"),"Deudor","Acreedor") -> Deudor | E22: =SUMPRODUCT(('Libro Diario'!$A$10:$A$5000=$B$4)*('Libro Diario'!$E$10:$E$5000=A22)*(YEAR('Libro Diario'!$C$10:$C$5000)=$E$4)*('Libro Diario'!$H$10:$H$5000)) -> 0 | F22: =SUMPRODUCT(('Libro Diario'!$A$10:$A$5000=$B$4)*('Libro Diario'!$E$10:$E$5000=A22)*(YEAR('Libro Diario'!$C$10:$C$5000)=$E$4)*('Libro Diario'!$I$10:$I$5000)) -> 0 | G22: =IF(E22>F22,E22-F22,"") | H22: =IF(F22>E22,F22-E22,"") | I22: =IF(OR(C22="ACTIVO",C22="PERDIDA"),E22-F22,F22-E22) -> 0
A23: 1107401 | B23: =IFERROR(INDEX(Cuentas!$C$8:$C$500,MATCH($B$4&"|"&A23,Cuentas!$A$8:$A$500&"|"&Cuentas!$B$8:$B$500,0)),"Contribuciones Bienes Raices- Credito") -> Contribuciones Bienes Raices- Credito | C23: =IFERROR(INDEX(Cuentas!$D$8:$D$500,MATCH($B$4&"|"&A23,Cuentas!$A$8:$A$500&"|"&Cuentas!$B$8:$B$500,0)),"ACTIVO") -> ACTIVO | D23: =IF(OR(C23="ACTIVO",C23="PERDIDA"),"Deudor","Acreedor") -> Deudor | E23: =SUMPRODUCT(('Libro Diario'!$A$10:$A$5000=$B$4)*('Libro Diario'!$E$10:$E$5000=A23)*(YEAR('Libro Diario'!$C$10:$C$5000)=$E$4)*('Libro Diario'!$H$10:$H$5000)) -> 0 | F23: =SUMPRODUCT(('Libro Diario'!$A$10:$A$5000=$B$4)*('Libro Diario'!$E$10:$E$5000=A23)*(YEAR('Libro Diario'!$C$10:$C$5000)=$E$4)*('Libro Diario'!$I$10:$I$5000)) -> 0 | G23: =IF(E23>F23,E23-F23,"") | H23: =IF(F23>E23,F23-E23,"") | I23: =IF(OR(C23="ACTIVO",C23="PERDIDA"),E23-F23,F23-E23) -> 0
A24: 1107402 | B24: =IFERROR(INDEX(Cuentas!$C$8:$C$500,MATCH($B$4&"|"&A24,Cuentas!$A$8:$A$500&"|"&Cuentas!$B$8:$B$500,0)),"Pagos Provisionales por Utilidades Absorbidas") -> Pagos Provisionales por Utilidades Absorbidas | C24: =IFERROR(INDEX(Cuentas!$D$8:$D$500,MATCH($B$4&"|"&A24,Cuentas!$A$8:$A$500&"|"&Cuentas!$B$8:$B$500,0)),"ACTIVO") -> ACTIVO | D24: =IF(OR(C24="ACTIVO",C24="PERDIDA"),"Deudor","Acreedor") -> Deudor | E24: =SUMPRODUCT(('Libro Diario'!$A$10:$A$5000=$B$4)*('Libro Diario'!$E$10:$E$5000=A24)*(YEAR('Libro Diario'!$C$10:$C$5000)=$E$4)*('Libro Diario'!$H$10:$H$5000)) -> 0 | F24: =SUMPRODUCT(('Libro Diario'!$A$10:$A$5000=$B$4)*('Libro Diario'!$E$10:$E$5000=A24)*(YEAR('Libro Diario'!$C$10:$C$5000)=$E$4)*('Libro Diario'!$I$10:$I$5000)) -> 0 | G24: =IF(E24>F24,E24-F24,"") | H24: =IF(F24>E24,F24-E24,"") | I24: =IF(OR(C24="ACTIVO",C24="PERDIDA"),E24-F24,F24-E24) -> 0
A25: 1107404 | B25: =IFERROR(INDEX(Cuentas!$C$8:$C$500,MATCH($B$4&"|"&A25,Cuentas!$A$8:$A$500&"|"&Cuentas!$B$8:$B$500,0)),"Credito Sence") -> Credito Sence | C25: =IFERROR(INDEX(Cuentas!$D$8:$D$500,MATCH($B$4&"|"&A25,Cuentas!$A$8:$A$500&"|"&Cuentas!$B$8:$B$500,0)),"ACTIVO") -> ACTIVO | D25: =IF(OR(C25="ACTIVO",C25="PERDIDA"),"Deudor","Acreedor") -> Deudor | E25: =SUMPRODUCT(('Libro Diario'!$A$10:$A$5000=$B$4)*('Libro Diario'!$E$10:$E$5000=A25)*(YEAR('Libro Diario'!$C$10:$C$5000)=$E$4)*('Libro Diario'!$H$10:$H$5000)) -> 0 | F25: =SUMPRODUCT(('Libro Diario'!$A$10:$A$5000=$B$4)*('Libro Diario'!$E$10:$E$5000=A25)*(YEAR('Libro Diario'!$C$10:$C$5000)=$E$4)*('Libro Diario'!$I$10:$I$5000)) -> 0 | G25: =IF(E25>F25,E25-F25,"") | H25: =IF(F25>E25,F25-E25,"") | I25: =IF(OR(C25="ACTIVO",C25="PERDIDA"),E25-F25,F25-E25) -> 0
A26: 1108001 | B26: =IFERROR(INDEX(Cuentas!$C$8:$C$500,MATCH($B$4&"|"&A26,Cuentas!$A$8:$A$500&"|"&Cuentas!$B$8:$B$500,0)),"Mercaderías") -> Mercaderías | C26: =IFERROR(INDEX(Cuentas!$D$8:$D$500,MATCH($B$4&"|"&A26,Cuentas!$A$8:$A$500&"|"&Cuentas!$B$8:$B$500,0)),"ACTIVO") -> ACTIVO | D26: =IF(OR(C26="ACTIVO",C26="PERDIDA"),"Deudor","Acreedor") -> Deudor | E26: =SUMPRODUCT(('Libro Diario'!$A$10:$A$5000=$B$4)*('Libro Diario'!$E$10:$E$5000=A26)*(YEAR('Libro Diario'!$C$10:$C$5000)=$E$4)*('Libro Diario'!$H$10:$H$5000)) -> 0 | F26: =SUMPRODUCT(('Libro Diario'!$A$10:$A$5000=$B$4)*('Libro Diario'!$E$10:$E$5000=A26)*(YEAR('Libro Diario'!$C$10:$C$5000)=$E$4)*('Libro Diario'!$I$10:$I$5000)) -> 0 | G26: =IF(E26>F26,E26-F26,"") | H26: =IF(F26>E26,F26-E26,"") | I26: =IF(OR(C26="ACTIVO",C26="PERDIDA"),E26-F26,F26-E26) -> 0
A27: 1108002 | B27: =IFERROR(INDEX(Cuentas!$C$8:$C$500,MATCH($B$4&"|"&A27,Cuentas!$A$8:$A$500&"|"&Cuentas!$B$8:$B$500,0)),"Materia Prima e Insumos") -> Materia Prima e Insumos | C27: =IFERROR(INDEX(Cuentas!$D$8:$D$500,MATCH($B$4&"|"&A27,Cuentas!$A$8:$A$500&"|"&Cuentas!$B$8:$B$500,0)),"ACTIVO") -> ACTIVO | D27: =IF(OR(C27="ACTIVO",C27="PERDIDA"),"Deudor","Acreedor") -> Deudor | E27: =SUMPRODUCT(('Libro Diario'!$A$10:$A$5000=$B$4)*('Libro Diario'!$E$10:$E$5000=A27)*(YEAR('Libro Diario'!$C$10:$C$5000)=$E$4)*('Libro Diario'!$H$10:$H$5000)) -> 0 | F27: =SUMPRODUCT(('Libro Diario'!$A$10:$A$5000=$B$4)*('Libro Diario'!$E$10:$E$5000=A27)*(YEAR('Libro Diario'!$C$10:$C$5000)=$E$4)*('Libro Diario'!$I$10:$I$5000)) -> 0 | G27: =IF(E27>F27,E27-F27,"") | H27: =IF(F27>E27,F27-E27,"") | I27: =IF(OR(C27="ACTIVO",C27="PERDIDA"),E27-F27,F27-E27) -> 0
A28: 1110001 | B28: =IFERROR(INDEX(Cuentas!$C$8:$C$500,MATCH($B$4&"|"&A28,Cuentas!$A$8:$A$500&"|"&Cuentas!$B$8:$B$500,0)),"Intereses diferidos Corto Plazo") -> Intereses diferidos Corto Plazo | C28: =IFERROR(INDEX(Cuentas!$D$8:$D$500,MATCH($B$4&"|"&A28,Cuentas!$A$8:$A$500&"|"&Cuentas!$B$8:$B$500,0)),"ACTIVO") -> ACTIVO | D28: =IF(OR(C28="ACTIVO",C28="PERDIDA"),"Deudor","Acreedor") -> Deudor | E28: =SUMPRODUCT(('Libro Diario'!$A$10:$A$5000=$B$4)*('Libro Diario'!$E$10:$E$5000=A28)*(YEAR('Libro Diario'!$C$10:$C$5000)=$E$4)*('Libro Diario'!$H$10:$H$5000)) -> 0 | F28: =SUMPRODUCT(('Libro Diario'!$A$10:$A$5000=$B$4)*('Libro Diario'!$E$10:$E$5000=A28)*(YEAR('Libro Diario'!$C$10:$C$5000)=$E$4)*('Libro Diario'!$I$10:$I$5000)) -> 0 | G28: =IF(E28>F28,E28-F28,"") | H28: =IF(F28>E28,F28-E28,"") | I28: =IF(OR(C28="ACTIVO",C28="PERDIDA"),E28-F28,F28-E28) -> 0
A29: 1201001 | B29: =IFERROR(INDEX(Cuentas!$C$8:$C$500,MATCH($B$4&"|"&A29,Cuentas!$A$8:$A$500&"|"&Cuentas!$B$8:$B$500,0)),"Vehiculos de Carga") -> Vehiculos de Carga | C29: =IFERROR(INDEX(Cuentas!$D$8:$D$500,MATCH($B$4&"|"&A29,Cuentas!$A$8:$A$500&"|"&Cuentas!$B$8:$B$500,0)),"ACTIVO") -> ACTIVO | D29: =IF(OR(C29="ACTIVO",C29="PERDIDA"),"Deudor","Acreedor") -> Deudor | E29: =SUMPRODUCT(('Libro Diario'!$A$10:$A$5000=$B$4)*('Libro Diario'!$E$10:$E$5000=A29)*(YEAR('Libro Diario'!$C$10:$C$5000)=$E$4)*('Libro Diario'!$H$10:$H$5000)) -> 0 | F29: =SUMPRODUCT(('Libro Diario'!$A$10:$A$5000=$B$4)*('Libro Diario'!$E$10:$E$5000=A29)*(YEAR('Libro Diario'!$C$10:$C$5000)=$E$4)*('Libro Diario'!$I$10:$I$5000)) -> 0 | G29: =IF(E29>F29,E29-F29,"") | H29: =IF(F29>E29,F29-E29,"") | I29: =IF(OR(C29="ACTIVO",C29="PERDIDA"),E29-F29,F29-E29) -> 0
A30: 1201002 | B30: =IFERROR(INDEX(Cuentas!$C$8:$C$500,MATCH($B$4&"|"&A30,Cuentas!$A$8:$A$500&"|"&Cuentas!$B$8:$B$500,0)),"Dep.Acum.Vehiculos de Carga") -> Dep.Acum.Vehiculos de Carga | C30: =IFERROR(INDEX(Cuentas!$D$8:$D$500,MATCH($B$4&"|"&A30,Cuentas!$A$8:$A$500&"|"&Cuentas!$B$8:$B$500,0)),"PASIVO") -> PASIVO | D30: =IF(OR(C30="ACTIVO",C30="PERDIDA"),"Deudor","Acreedor") -> Acreedor | E30: =SUMPRODUCT(('Libro Diario'!$A$10:$A$5000=$B$4)*('Libro Diario'!$E$10:$E$5000=A30)*(YEAR('Libro Diario'!$C$10:$C$5000)=$E$4)*('Libro Diario'!$H$10:$H$5000)) -> 0 | F30: =SUMPRODUCT(('Libro Diario'!$A$10:$A$5000=$B$4)*('Libro Diario'!$E$10:$E$5000=A30)*(YEAR('Libro Diario'!$C$10:$C$5000)=$E$4)*('Libro Diario'!$I$10:$I$5000)) -> 0 | G30: =IF(E30>F30,E30-F30,"") | H30: =IF(F30>E30,F30-E30,"") | I30: =IF(OR(C30="ACTIVO",C30="PERDIDA"),E30-F30,F30-E30) -> 0
A31: 1201003 | B31: =IFERROR(INDEX(Cuentas!$C$8:$C$500,MATCH($B$4&"|"&A31,Cuentas!$A$8:$A$500&"|"&Cuentas!$B$8:$B$500,0)),"Otros Vehiculos de Trabajo") -> Otros Vehiculos de Trabajo | C31: =IFERROR(INDEX(Cuentas!$D$8:$D$500,MATCH($B$4&"|"&A31,Cuentas!$A$8:$A$500&"|"&Cuentas!$B$8:$B$500,0)),"ACTIVO") -> ACTIVO | D31: =IF(OR(C31="ACTIVO",C31="PERDIDA"),"Deudor","Acreedor") -> Deudor | E31: =SUMPRODUCT(('Libro Diario'!$A$10:$A$5000=$B$4)*('Libro Diario'!$E$10:$E$5000=A31)*(YEAR('Libro Diario'!$C$10:$C$5000)=$E$4)*('Libro Diario'!$H$10:$H$5000)) -> 0 | F31: =SUMPRODUCT(('Libro Diario'!$A$10:$A$5000=$B$4)*('Libro Diario'!$E$10:$E$5000=A31)*(YEAR('Libro Diario'!$C$10:$C$5000)=$E$4)*('Libro Diario'!$I$10:$I$5000)) -> 0 | G31: =IF(E31>F31,E31-F31,"") | H31: =IF(F31>E31,F31-E31,"") | I31: =IF(OR(C31="ACTIVO",C31="PERDIDA"),E31-F31,F31-E31) -> 0
A32: 1201004 | B32: =IFERROR(INDEX(Cuentas!$C$8:$C$500,MATCH($B$4&"|"&A32,Cuentas!$A$8:$A$500&"|"&Cuentas!$B$8:$B$500,0)),"Dep. Acum. Vehículos") -> Dep. Acum. Vehículos | C32: =IFERROR(INDEX(Cuentas!$D$8:$D$500,MATCH($B$4&"|"&A32,Cuentas!$A$8:$A$500&"|"&Cuentas!$B$8:$B$500,0)),"PASIVO") -> PASIVO | D32: =IF(OR(C32="ACTIVO",C32="PERDIDA"),"Deudor","Acreedor") -> Acreedor | E32: =SUMPRODUCT(('Libro Diario'!$A$10:$A$5000=$B$4)*('Libro Diario'!$E$10:$E$5000=A32)*(YEAR('Libro Diario'!$C$10:$C$5000)=$E$4)*('Libro Diario'!$H$10:$H$5000)) -> 0 | F32: =SUMPRODUCT(('Libro Diario'!$A$10:$A$5000=$B$4)*('Libro Diario'!$E$10:$E$5000=A32)*(YEAR('Libro Diario'!$C$10:$C$5000)=$E$4)*('Libro Diario'!$I$10:$I$5000)) -> 0 | G32: =IF(E32>F32,E32-F32,"") | H32: =IF(F32>E32,F32-E32,"") | I32: =IF(OR(C32="ACTIVO",C32="PERDIDA"),E32-F32,F32-E32) -> 0
A33: 1201005 | B33: =IFERROR(INDEX(Cuentas!$C$8:$C$500,MATCH($B$4&"|"&A33,Cuentas!$A$8:$A$500&"|"&Cuentas!$B$8:$B$500,0)),"Remolques , carros") -> Remolques , carros | C33: =IFERROR(INDEX(Cuentas!$D$8:$D$500,MATCH($B$4&"|"&A33,Cuentas!$A$8:$A$500&"|"&Cuentas!$B$8:$B$500,0)),"ACTIVO") -> ACTIVO | D33: =IF(OR(C33="ACTIVO",C33="PERDIDA"),"Deudor","Acreedor") -> Deudor | E33: =SUMPRODUCT(('Libro Diario'!$A$10:$A$5000=$B$4)*('Libro Diario'!$E$10:$E$5000=A33)*(YEAR('Libro Diario'!$C$10:$C$5000)=$E$4)*('Libro Diario'!$H$10:$H$5000)) -> 0 | F33: =SUMPRODUCT(('Libro Diario'!$A$10:$A$5000=$B$4)*('Libro Diario'!$E$10:$E$5000=A33)*(YEAR('Libro Diario'!$C$10:$C$5000)=$E$4)*('Libro Diario'!$I$10:$I$5000)) -> 0 | G33: =IF(E33>F33,E33-F33,"") | H33: =IF(F33>E33,F33-E33,"") | I33: =IF(OR(C33="ACTIVO",C33="PERDIDA"),E33-F33,F33-E33) -> 0
A34: 1201006 | B34: =IFERROR(INDEX(Cuentas!$C$8:$C$500,MATCH($B$4&"|"&A34,Cuentas!$A$8:$A$500&"|"&Cuentas!$B$8:$B$500,0)),"Dep.Acum.Remolques, carros") -> Dep.Acum.Remolques, carros | C34: =IFERROR(INDEX(Cuentas!$D$8:$D$500,MATCH($B$4&"|"&A34,Cuentas!$A$8:$A$500&"|"&Cuentas!$B$8:$B$500,0)),"PASIVO") -> PASIVO | D34: =IF(OR(C34="ACTIVO",C34="PERDIDA"),"Deudor","Acreedor") -> Acreedor | E34: =SUMPRODUCT(('Libro Diario'!$A$10:$A$5000=$B$4)*('Libro Diario'!$E$10:$E$5000=A34)*(YEAR('Libro Diario'!$C$10:$C$5000)=$E$4)*('Libro Diario'!$H$10:$H$5000)) -> 0 | F34: =SUMPRODUCT(('Libro Diario'!$A$10:$A$5000=$B$4)*('Libro Diario'!$E$10:$E$5000=A34)*(YEAR('Libro Diario'!$C$10:$C$5000)=$E$4)*('Libro Diario'!$I$10:$I$5000)) -> 0 | G34: =IF(E34>F34,E34-F34,"") | H34: =IF(F34>E34,F34-E34,"") | I34: =IF(OR(C34="ACTIVO",C34="PERDIDA"),E34-F34,F34-E34) -> 0
A35: 1201007 | B35: =IFERROR(INDEX(Cuentas!$C$8:$C$500,MATCH($B$4&"|"&A35,Cuentas!$A$8:$A$500&"|"&Cuentas!$B$8:$B$500,0)),"Vehiculos") -> Vehiculos | C35: =IFERROR(INDEX(Cuentas!$D$8:$D$500,MATCH($B$4&"|"&A35,Cuentas!$A$8:$A$500&"|"&Cuentas!$B$8:$B$500,0)),"ACTIVO") -> ACTIVO | D35: =IF(OR(C35="ACTIVO",C35="PERDIDA"),"Deudor","Acreedor") -> Deudor | E35: =SUMPRODUCT(('Libro Diario'!$A$10:$A$5000=$B$4)*('Libro Diario'!$E$10:$E$5000=A35)*(YEAR('Libro Diario'!$C$10:$C$5000)=$E$4)*('Libro Diario'!$H$10:$H$5000)) -> 0 | F35: =SUMPRODUCT(('Libro Diario'!$A$10:$A$5000=$B$4)*('Libro Diario'!$E$10:$E$5000=A35)*(YEAR('Libro Diario'!$C$10:$C$5000)=$E$4)*('Libro Diario'!$I$10:$I$5000)) -> 0 | G35: =IF(E35>F35,E35-F35,"") | H35: =IF(F35>E35,F35-E35,"") | I35: =IF(OR(C35="ACTIVO",C35="PERDIDA"),E35-F35,F35-E35) -> 0
A36: 1201008 | B36: =IFERROR(INDEX(Cuentas!$C$8:$C$500,MATCH($B$4&"|"&A36,Cuentas!$A$8:$A$500&"|"&Cuentas!$B$8:$B$500,0)),"Vehiculos en Leasing") -> Vehiculos en Leasing | C36: =IFERROR(INDEX(Cuentas!$D$8:$D$500,MATCH($B$4&"|"&A36,Cuentas!$A$8:$A$500&"|"&Cuentas!$B$8:$B$500,0)),"ACTIVO") -> ACTIVO | D36: =IF(OR(C36="ACTIVO",C36="PERDIDA"),"Deudor","Acreedor") -> Deudor | E36: =SUMPRODUCT(('Libro Diario'!$A$10:$A$5000=$B$4)*('Libro Diario'!$E$10:$E$5000=A36)*(YEAR('Libro Diario'!$C$10:$C$5000)=$E$4)*('Libro Diario'!$H$10:$H$5000)) -> 0 | F36: =SUMPRODUCT(('Libro Diario'!$A$10:$A$5000=$B$4)*('Libro Diario'!$E$10:$E$5000=A36)*(YEAR('Libro Diario'!$C$10:$C$5000)=$E$4)*('Libro Diario'!$I$10:$I$5000)) -> 0 | G36: =IF(E36>F36,E36-F36,"") | H36: =IF(F36>E36,F36-E36,"") | I36: =IF(OR(C36="ACTIVO",C36="PERDIDA"),E36-F36,F36-E36) -> 0
A37: 1201010 | B37: =IFERROR(INDEX(Cuentas!$C$8:$C$500,MATCH($B$4&"|"&A37,Cuentas!$A$8:$A$500&"|"&Cuentas!$B$8:$B$500,0)),"Dif.Valor Comercial Vehiculos") -> Dif.Valor Comercial Vehiculos | C37: =IFERROR(INDEX(Cuentas!$D$8:$D$500,MATCH($B$4&"|"&A37,Cuentas!$A$8:$A$500&"|"&Cuentas!$B$8:$B$500,0)),"ACTIVO") -> ACTIVO | D37: =IF(OR(C37="ACTIVO",C37="PERDIDA"),"Deudor","Acreedor") -> Deudor | E37: =SUMPRODUCT(('Libro Diario'!$A$10:$A$5000=$B$4)*('Libro Diario'!$E$10:$E$5000=A37)*(YEAR('Libro Diario'!$C$10:$C$5000)=$E$4)*('Libro Diario'!$H$10:$H$5000)) -> 0 | F37: =SUMPRODUCT(('Libro Diario'!$A$10:$A$5000=$B$4)*('Libro Diario'!$E$10:$E$5000=A37)*(YEAR('Libro Diario'!$C$10:$C$5000)=$E$4)*('Libro Diario'!$I$10:$I$5000)) -> 0 | G37: =IF(E37>F37,E37-F37,"") | H37: =IF(F37>E37,F37-E37,"") | I37: =IF(OR(C37="ACTIVO",C37="PERDIDA"),E37-F37,F37-E37) -> 0
A38: 1202001 | B38: =IFERROR(INDEX(Cuentas!$C$8:$C$500,MATCH($B$4&"|"&A38,Cuentas!$A$8:$A$500&"|"&Cuentas!$B$8:$B$500,0)),"Gruas") -> Gruas | C38: =IFERROR(INDEX(Cuentas!$D$8:$D$500,MATCH($B$4&"|"&A38,Cuentas!$A$8:$A$500&"|"&Cuentas!$B$8:$B$500,0)),"ACTIVO") -> ACTIVO | D38: =IF(OR(C38="ACTIVO",C38="PERDIDA"),"Deudor","Acreedor") -> Deudor | E38: =SUMPRODUCT(('Libro Diario'!$A$10:$A$5000=$B$4)*('Libro Diario'!$E$10:$E$5000=A38)*(YEAR('Libro Diario'!$C$10:$C$5000)=$E$4)*('Libro Diario'!$H$10:$H$5000)) -> 0 | F38: =SUMPRODUCT(('Libro Diario'!$A$10:$A$5000=$B$4)*('Libro Diario'!$E$10:$E$5000=A38)*(YEAR('Libro Diario'!$C$10:$C$5000)=$E$4)*('Libro Diario'!$I$10:$I$5000)) -> 0 | G38: =IF(E38>F38,E38-F38,"") | H38: =IF(F38>E38,F38-E38,"") | I38: =IF(OR(C38="ACTIVO",C38="PERDIDA"),E38-F38,F38-E38) -> 0
A39: 1202003 | B39: =IFERROR(INDEX(Cuentas!$C$8:$C$500,MATCH($B$4&"|"&A39,Cuentas!$A$8:$A$500&"|"&Cuentas!$B$8:$B$500,0)),"Tractores") -> Tractores | C39: =IFERROR(INDEX(Cuentas!$D$8:$D$500,MATCH($B$4&"|"&A39,Cuentas!$A$8:$A$500&"|"&Cuentas!$B$8:$B$500,0)),"ACTIVO") -> ACTIVO | D39: =IF(OR(C39="ACTIVO",C39="PERDIDA"),"Deudor","Acreedor") -> Deudor | E39: =SUMPRODUCT(('Libro Diario'!$A$10:$A$5000=$B$4)*('Libro Diario'!$E$10:$E$5000=A39)*(YEAR('Libro Diario'!$C$10:$C$5000)=$E$4)*('Libro Diario'!$H$10:$H$5000)) -> 0 | F39: =SUMPRODUCT(('Libro Diario'!$A$10:$A$5000=$B$4)*('Libro Diario'!$E$10:$E$5000=A39)*(YEAR('Libro Diario'!$C$10:$C$5000)=$E$4)*('Libro Diario'!$I$10:$I$5000)) -> 0 | G39: =IF(E39>F39,E39-F39,"") | H39: =IF(F39>E39,F39-E39,"") | I39: =IF(OR(C39="ACTIVO",C39="PERDIDA"),E39-F39,F39-E39) -> 0
A40: 1202004 | B40: =IFERROR(INDEX(Cuentas!$C$8:$C$500,MATCH($B$4&"|"&A40,Cuentas!$A$8:$A$500&"|"&Cuentas!$B$8:$B$500,0)),"Maquinas y equipos") -> Maquinas y equipos | C40: =IFERROR(INDEX(Cuentas!$D$8:$D$500,MATCH($B$4&"|"&A40,Cuentas!$A$8:$A$500&"|"&Cuentas!$B$8:$B$500,0)),"ACTIVO") -> ACTIVO | D40: =IF(OR(C40="ACTIVO",C40="PERDIDA"),"Deudor","Acreedor") -> Deudor | E40: =SUMPRODUCT(('Libro Diario'!$A$10:$A$5000=$B$4)*('Libro Diario'!$E$10:$E$5000=A40)*(YEAR('Libro Diario'!$C$10:$C$5000)=$E$4)*('Libro Diario'!$H$10:$H$5000)) -> 0 | F40: =SUMPRODUCT(('Libro Diario'!$A$10:$A$5000=$B$4)*('Libro Diario'!$E$10:$E$5000=A40)*(YEAR('Libro Diario'!$C$10:$C$5000)=$E$4)*('Libro Diario'!$I$10:$I$5000)) -> 0 | G40: =IF(E40>F40,E40-F40,"") | H40: =IF(F40>E40,F40-E40,"") | I40: =IF(OR(C40="ACTIVO",C40="PERDIDA"),E40-F40,F40-E40) -> 0
A41: 1202005 | B41: =IFERROR(INDEX(Cuentas!$C$8:$C$500,MATCH($B$4&"|"&A41,Cuentas!$A$8:$A$500&"|"&Cuentas!$B$8:$B$500,0)),"Equipos Computacionales y relacionados") -> Equipos Computacionales y relacionados | C41: =IFERROR(INDEX(Cuentas!$D$8:$D$500,MATCH($B$4&"|"&A41,Cuentas!$A$8:$A$500&"|"&Cuentas!$B$8:$B$500,0)),"ACTIVO") -> ACTIVO | D41: =IF(OR(C41="ACTIVO",C41="PERDIDA"),"Deudor","Acreedor") -> Deudor | E41: =SUMPRODUCT(('Libro Diario'!$A$10:$A$5000=$B$4)*('Libro Diario'!$E$10:$E$5000=A41)*(YEAR('Libro Diario'!$C$10:$C$5000)=$E$4)*('Libro Diario'!$H$10:$H$5000)) -> 0 | F41: =SUMPRODUCT(('Libro Diario'!$A$10:$A$5000=$B$4)*('Libro Diario'!$E$10:$E$5000=A41)*(YEAR('Libro Diario'!$C$10:$C$5000)=$E$4)*('Libro Diario'!$I$10:$I$5000)) -> 0 | G41: =IF(E41>F41,E41-F41,"") | H41: =IF(F41>E41,F41-E41,"") | I41: =IF(OR(C41="ACTIVO",C41="PERDIDA"),E41-F41,F41-E41) -> 0
...

Sheet Balance General
A1: BALANCE GENERAL — ESTADO DE SITUACIÓN FINANCIERA
A3: ⚖ NORMATIVA: NIIF para Pymes — obligatoria en Chile desde 2013 (Boletín Técnico N°82, Colegio de Contadores A.G.). Empresas con ingresos > 100.000 UF aplican NIIF Completas bajo supervisión CMF. Estructura clasificada Corriente/No Corriente según Sección 4 NIIF Pymes. Tercera edición NIIF Pymes aplicable desde el 1 de enero de 2027. Para fines tributarios: Balance de 8 Columnas — Formulario I001 (Grandes/Medianas) o I002 (Micro/Pequeñas), presentado con F-22 antes del 30 de junio.
A5: Cliente: | B5: CLI001 | C5: Período (Año): | D5: 2025
A7: =IFERROR(INDEX(Clientes!$C$4:$C$200,MATCH(B5,Clientes!$A$4:$A$200,0)),"[Seleccione un cliente]")&" — Balance General al 31 de Diciembre de "&TEXT(D5,"0") -> ← Ingrese aquí su primer cliente — Balance General al 31 de Diciembre de 2025
A8: RUBRO / CUENTA | D8: MONTO ($)
A9: A C T I V O S
A10: ACTIVO CORRIENTE
A11: Sec. 4.5 NIIF Pymes: Activos cuya realización se espera dentro de 12 meses o del ciclo normal de operación.
A12: Efectivo y Equivalentes — Caja | C12: Sec. 7 NIIF Pymes | Activo más líquido | D12: =SUMPRODUCT(('Libro Diario'!$A$10:$A$5000=$B$5)*('Libro Diario'!$E$10:$E$5000=1101001)*(YEAR('Libro Diario'!$C$10:$C$5000)=$D$5)*('Libro Diario'!$H$10:$H$5000))-SUMPRODUCT(('Libro Diario'!$A$10:$A$5000=$B$5)*('Libro Diario'!$E$10:$E$5000=1101001)*(YEAR('Libro Diario'!$C$10:$C$5000)=$D$5)*('Libro Diario'!$I$10:$I$5000)) -> 0
A13: Efectivo y Equivalentes — Bancos | C13: Sec. 7 NIIF Pymes | Incluye depósitos vista | D13: =SUMPRODUCT(('Libro Diario'!$A$10:$A$5000=$B$5)*('Libro Diario'!$E$10:$E$5000=1101002)*(YEAR('Libro Diario'!$C$10:$C$5000)=$D$5)*('Libro Diario'!$H$10:$H$5000))-SUMPRODUCT(('Libro Diario'!$A$10:$A$5000=$B$5)*('Libro Diario'!$E$10:$E$5000=1101002)*(YEAR('Libro Diario'!$C$10:$C$5000)=$D$5)*('Libro Diario'!$I$10:$I$5000)) -> 0
A14: Cuentas por Cobrar Comerciales | C14: Sec. 11 NIIF Pymes | Valor neto de recuperación | D14: =SUMPRODUCT(('Libro Diario'!$A$10:$A$5000=$B$5)*('Libro Diario'!$E$10:$E$5000=1104001)*(YEAR('Libro Diario'!$C$10:$C$5000)=$D$5)*('Libro Diario'!$H$10:$H$5000))-SUMPRODUCT(('Libro Diario'!$A$10:$A$5000=$B$5)*('Libro Diario'!$E$10:$E$5000=1104001)*(YEAR('Libro Diario'!$C$10:$C$5000)=$D$5)*('Libro Diario'!$I$10:$I$5000)) -> 0
A15: Retiros Acumulados Ej. Anteriores | C15: PCGA Chile | Cuenta socios | D15: =SUMPRODUCT(('Libro Diario'!$A$10:$A$5000=$B$5)*('Libro Diario'!$E$10:$E$5000=1106001)*(YEAR('Libro Diario'!$C$10:$C$5000)=$D$5)*('Libro Diario'!$H$10:$H$5000))-SUMPRODUCT(('Libro Diario'!$A$10:$A$5000=$B$5)*('Libro Diario'!$E$10:$E$5000=1106001)*(YEAR('Libro Diario'!$C$10:$C$5000)=$D$5)*('Libro Diario'!$I$10:$I$5000)) -> 0
A16: Cta. Cte. Socio (1) | C16: Sec. 22 NIIF Pymes | Partes relacionadas | D16: =SUMPRODUCT(('Libro Diario'!$A$10:$A$5000=$B$5)*('Libro Diario'!$E$10:$E$5000=1106002)*(YEAR('Libro Diario'!$C$10:$C$5000)=$D$5)*('Libro Diario'!$H$10:$H$5000))-SUMPRODUCT(('Libro Diario'!$A$10:$A$5000=$B$5)*('Libro Diario'!$E$10:$E$5000=1106002)*(YEAR('Libro Diario'!$C$10:$C$5000)=$D$5)*('Libro Diario'!$I$10:$I$5000)) -> 0
A17: Cta. Cte. Socio (2) | C17: Sec. 22 NIIF Pymes | Partes relacionadas | D17: =SUMPRODUCT(('Libro Diario'!$A$10:$A$5000=$B$5)*('Libro Diario'!$E$10:$E$5000=1106003)*(YEAR('Libro Diario'!$C$10:$C$5000)=$D$5)*('Libro Diario'!$H$10:$H$5000))-SUMPRODUCT(('Libro Diario'!$A$10:$A$5000=$B$5)*('Libro Diario'!$E$10:$E$5000=1106003)*(YEAR('Libro Diario'!$C$10:$C$5000)=$D$5)*('Libro Diario'!$I$10:$I$5000)) -> 0
A18: IVA Crédito Fiscal 19% | C18: Art. 23 D.L. 825 | Recuperable F-29 | D18: =SUMPRODUCT(('Libro Diario'!$A$10:$A$5000=$B$5)*('Libro Diario'!$E$10:$E$5000=1107101)*(YEAR('Libro Diario'!$C$10:$C$5000)=$D$5)*('Libro Diario'!$H$10:$H$5000))-SUMPRODUCT(('Libro Diario'!$A$10:$A$5000=$B$5)*('Libro Diario'!$E$10:$E$5000=1107101)*(YEAR('Libro Diario'!$C$10:$C$5000)=$D$5)*('Libro Diario'!$I$10:$I$5000)) -> 0
A19: IVA CF No Retenido 11% | C19: Art. 11 D.L. 825 | Retención parcial | D19: =SUMPRODUCT(('Libro Diario'!$A$10:$A$5000=$B$5)*('Libro Diario'!$E$10:$E$5000=1107103)*(YEAR('Libro Diario'!$C$10:$C$5000)=$D$5)*('Libro Diario'!$H$10:$H$5000))-SUMPRODUCT(('Libro Diario'!$A$10:$A$5000=$B$5)*('Libro Diario'!$E$10:$E$5000=1107103)*(YEAR('Libro Diario'!$C$10:$C$5000)=$D$5)*('Libro Diario'!$I$10:$I$5000)) -> 0
A20: PPM (Pagos Prov. Mensuales) | C20: Art. 84 LIR | Crédito Impuesto 1ª Cat. | D20: =SUMPRODUCT(('Libro Diario'!$A$10:$A$5000=$B$5)*('Libro Diario'!$E$10:$E$5000=1107201)*(YEAR('Libro Diario'!$C$10:$C$5000)=$D$5)*('Libro Diario'!$H$10:$H$5000))-SUMPRODUCT(('Libro Diario'!$A$10:$A$5000=$B$5)*('Libro Diario'!$E$10:$E$5000=1107201)*(YEAR('Libro Diario'!$C$10:$C$5000)=$D$5)*('Libro Diario'!$I$10:$I$5000)) -> 0
A21: Crédito Diesel Transporte Carga | C21: Art. 7° Ley 18.502 | D21: =SUMPRODUCT(('Libro Diario'!$A$10:$A$5000=$B$5)*('Libro Diario'!$E$10:$E$5000=1107301)*(YEAR('Libro Diario'!$C$10:$C$5000)=$D$5)*('Libro Diario'!$H$10:$H$5000))-SUMPRODUCT(('Libro Diario'!$A$10:$A$5000=$B$5)*('Libro Diario'!$E$10:$E$5000=1107301)*(YEAR('Libro Diario'!$C$10:$C$5000)=$D$5)*('Libro Diario'!$I$10:$I$5000)) -> 0
A22: Art. 33 bis (4%) Activo Fijo | C22: Art. 33 bis LIR | Crédito inversión AF | D22: =SUMPRODUCT(('Libro Diario'!$A$10:$A$5000=$B$5)*('Libro Diario'!$E$10:$E$5000=1107302)*(YEAR('Libro Diario'!$C$10:$C$5000)=$D$5)*('Libro Diario'!$H$10:$H$5000))-SUMPRODUCT(('Libro Diario'!$A$10:$A$5000=$B$5)*('Libro Diario'!$E$10:$E$5000=1107302)*(YEAR('Libro Diario'!$C$10:$C$5000)=$D$5)*('Libro Diario'!$I$10:$I$5000)) -> 0
A23: Contrib. Bienes Raíces — Crédito | C23: Art. 33 bis LIR | D23: =SUMPRODUCT(('Libro Diario'!$A$10:$A$5000=$B$5)*('Libro Diario'!$E$10:$E$5000=1107401)*(YEAR('Libro Diario'!$C$10:$C$5000)=$D$5)*('Libro Diario'!$H$10:$H$5000))-SUMPRODUCT(('Libro Diario'!$A$10:$A$5000=$B$5)*('Libro Diario'!$E$10:$E$5000=1107401)*(YEAR('Libro Diario'!$C$10:$C$5000)=$D$5)*('Libro Diario'!$I$10:$I$5000)) -> 0
A24: PPUA | C24: Art. 31 N°3 LIR | Pérdidas tributarias | D24: =SUMPRODUCT(('Libro Diario'!$A$10:$A$5000=$B$5)*('Libro Diario'!$E$10:$E$5000=1107402)*(YEAR('Libro Diario'!$C$10:$C$5000)=$D$5)*('Libro Diario'!$H$10:$H$5000))-SUMPRODUCT(('Libro Diario'!$A$10:$A$5000=$B$5)*('Libro Diario'!$E$10:$E$5000=1107402)*(YEAR('Libro Diario'!$C$10:$C$5000)=$D$5)*('Libro Diario'!$I$10:$I$5000)) -> 0
A25: Crédito SENCE | C25: Ley 19.518 | Recuperable F-29 | D25: =SUMPRODUCT(('Libro Diario'!$A$10:$A$5000=$B$5)*('Libro Diario'!$E$10:$E$5000=1107404)*(YEAR('Libro Diario'!$C$10:$C$5000)=$D$5)*('Libro Diario'!$H$10:$H$5000))-SUMPRODUCT(('Libro Diario'!$A$10:$A$5000=$B$5)*('Libro Diario'!$E$10:$E$5000=1107404)*(YEAR('Libro Diario'!$C$10:$C$5000)=$D$5)*('Libro Diario'!$I$10:$I$5000)) -> 0
A26: Mercaderías | C26: Sec. 13 NIIF Pymes | Min(costo, VNR) | D26: =SUMPRODUCT(('Libro Diario'!$A$10:$A$5000=$B$5)*('Libro Diario'!$E$10:$E$5000=1108001)*(YEAR('Libro Diario'!$C$10:$C$5000)=$D$5)*('Libro Diario'!$H$10:$H$5000))-SUMPRODUCT(('Libro Diario'!$A$10:$A$5000=$B$5)*('Libro Diario'!$E$10:$E$5000=1108001)*(YEAR('Libro Diario'!$C$10:$C$5000)=$D$5)*('Libro Diario'!$I$10:$I$5000)) -> 0
A27: Materia Prima e Insumos | C27: Sec. 13 NIIF Pymes | FIFO o CMP | D27: =SUMPRODUCT(('Libro Diario'!$A$10:$A$5000=$B$5)*('Libro Diario'!$E$10:$E$5000=1108002)*(YEAR('Libro Diario'!$C$10:$C$5000)=$D$5)*('Libro Diario'!$H$10:$H$5000))-SUMPRODUCT(('Libro Diario'!$A$10:$A$5000=$B$5)*('Libro Diario'!$E$10:$E$5000=1108002)*(YEAR('Libro Diario'!$C$10:$C$5000)=$D$5)*('Libro Diario'!$I$10:$I$5000)) -> 0
A28: Intereses Diferidos CP | C28: Sec. 11 NIIF Pymes | Costo amortizado | D28: =SUMPRODUCT(('Libro Diario'!$A$10:$A$5000=$B$5)*('Libro Diario'!$E$10:$E$5000=1110001)*(YEAR('Libro Diario'!$C$10:$C$5000)=$D$5)*('Libro Diario'!$H$10:$H$5000))-SUMPRODUCT(('Libro Diario'!$A$10:$A$5000=$B$5)*('Libro Diario'!$E$10:$E$5000=1110001)*(YEAR('Libro Diario'!$C$10:$C$5000)=$D$5)*('Libro Diario'!$I$10:$I$5000)) -> 0
A29: TOTAL ACTIVO CORRIENTE | D29: =SUM(D12:D28) -> 0
A31: ACTIVO NO CORRIENTE
A32: Sec. 4.5 NIIF Pymes: Activos no corrientes. Se presentan netos de depreciación acumulada. Terrenos no se deprecian (Sec. 17.15). Leasing financiero se activa (Sec. 20.9).
A33: Vehículos de Carga (Bruto) | C33: Sec. 17 NIIF Pymes | Modelo del Costo | D33: =SUMPRODUCT(('Libro Diario'!$A$10:$A$5000=$B$5)*('Libro Diario'!$E$10:$E$5000=1201001)*(YEAR('Libro Diario'!$C$10:$C$5000)=$D$5)*('Libro Diario'!$H$10:$H$5000))-SUMPRODUCT(('Libro Diario'!$A$10:$A$5000=$B$5)*('Libro Diario'!$E$10:$E$5000=1201001)*(YEAR('Libro Diario'!$C$10:$C$5000)=$D$5)*('Libro Diario'!$I$10:$I$5000)) -> 0
A34: (-) Dep. Acum. Vehículos de Carga | C34: SII: vida útil 7 años (Res. Ex. 43/2002) | D34: =SUMPRODUCT(('Libro Diario'!$A$10:$A$5000=$B$5)*('Libro Diario'!$E$10:$E$5000=1201002)*(YEAR('Libro Diario'!$C$10:$C$5000)=$D$5)*('Libro Diario'!$H$10:$H$5000))-SUMPRODUCT(('Libro Diario'!$A$10:$A$5000=$B$5)*('Libro Diario'!$E$10:$E$5000=1201002)*(YEAR('Libro Diario'!$C$10:$C$5000)=$D$5)*('Libro Diario'!$I$10:$I$5000)) -> 0
A35: Otros Vehículos (Bruto) | C35: Sec. 17 NIIF Pymes | D35: =SUMPRODUCT(('Libro Diario'!$A$10:$A$5000=$B$5)*('Libro Diario'!$E$10:$E$5000=1201003)*(YEAR('Libro Diario'!$C$10:$C$5000)=$D$5)*('Libro Diario'!$H$10:$H$5000))-SUMPRODUCT(('Libro Diario'!$A$10:$A$5000=$B$5)*('Libro Diario'!$E$10:$E$5000=1201003)*(YEAR('Libro Diario'!$C$10:$C$5000)=$D$5)*('Libro Diario'!$I$10:$I$5000)) -> 0
A36: (-) Dep. Acum. Otros Vehículos | C36: SII: tabla vida útil Res. Ex. 43/2002 | D36: =SUMPRODUCT(('Libro Diario'!$A$10:$A$5000=$B$5)*('Libro Diario'!$E$10:$E$5000=1201004)*(YEAR('Libro Diario'!$C$10:$C$5000)=$D$5)*('Libro Diario'!$H$10:$H$5000))-SUMPRODUCT(('Libro Diario'!$A$10:$A$5000=$B$5)*('Libro Diario'!$E$10:$E$5000=1201004)*(YEAR('Libro Diario'!$C$10:$C$5000)=$D$5)*('Libro Diario'!$I$10:$I$5000)) -> 0
A37: Remolques y Carros (Bruto) | C37: Sec. 17 NIIF Pymes | D37: =SUMPRODUCT(('Libro Diario'!$A$10:$A$5000=$B$5)*('Libro Diario'!$E$10:$E$5000=1201005)*(YEAR('Libro Diario'!$C$10:$C$5000)=$D$5)*('Libro Diario'!$H$10:$H$5000))-SUMPRODUCT(('Libro Diario'!$A$10:$A$5000=$B$5)*('Libro Diario'!$E$10:$E$5000=1201005)*(YEAR('Libro Diario'!$C$10:$C$5000)=$D$5)*('Libro Diario'!$I$10:$I$5000)) -> 0
A38: (-) Dep. Acum. Remolques | C38: SII: según tabla de vida útil | D38: =SUMPRODUCT(('Libro Diario'!$A$10:$A$5000=$B$5)*('Libro Diario'!$E$10:$E$5000=1201006)*(YEAR('Libro Diario'!$C$10:$C$5000)=$D$5)*('Libro Diario'!$H$10:$H$5000))-SUMPRODUCT(('Libro Diario'!$A$10:$A$5000=$B$5)*('Libro Diario'!$E$10:$E$5000=1201006)*(YEAR('Libro Diario'!$C$10:$C$5000)=$D$5)*('Libro Diario'!$I$10:$I$5000)) -> 0
A39: Vehículos (Bruto) | C39: Sec. 17 NIIF Pymes | D39: =SUMPRODUCT(('Libro Diario'!$A$10:$A$5000=$B$5)*('Libro Diario'!$E$10:$E$5000=1201007)*(YEAR('Libro Diario'!$C$10:$C$5000)=$D$5)*('Libro Diario'!$H$10:$H$5000))-SUMPRODUCT(('Libro Diario'!$A$10:$A$5000=$B$5)*('Libro Diario'!$E$10:$E$5000=1201007)*(YEAR('Libro Diario'!$C$10:$C$5000)=$D$5)*('Libro Diario'!$I$10:$I$5000)) -> 0
A40: Vehículos en Leasing | C40: Sec. 20 NIIF Pymes | Activo arrendado | D40: =SUMPRODUCT(('Libro Diario'!$A$10:$A$5000=$B$5)*('Libro Diario'!$E$10:$E$5000=1201008)*(YEAR('Libro Diario'!$C$10:$C$5000)=$D$5)*('Libro Diario'!$H$10:$H$5000))-SUMPRODUCT(('Libro Diario'!$A$10:$A$5000=$B$5)*('Libro Diario'!$E$10:$E$5000=1201008)*(YEAR('Libro Diario'!$C$10:$C$5000)=$D$5)*('Libro Diario'!$I$10:$I$5000)) -> 0
A41: Dif. Valor Comercial Vehículos | C41: Ajuste valor libro vs. comercial | D41: =SUMPRODUCT(('Libro Diario'!$A$10:$A$5000=$B$5)*('Libro Diario'!$E$10:$E$5000=1201010)*(YEAR('Libro Diario'!$C$10:$C$5000)=$D$5)*('Libro Diario'!$H$10:$H$5000))-SUMPRODUCT(('Libro Diario'!$A$10:$A$5000=$B$5)*('Libro Diario'!$E$10:$E$5000=1201010)*(YEAR('Libro Diario'!$C$10:$C$5000)=$D$5)*('Libro Diario'!$I$10:$I$5000)) -> 0
A42: Grúas (Bruto) | C42: Sec. 17 NIIF Pymes | D42: =SUMPRODUCT(('Libro Diario'!$A$10:$A$5000=$B$5)*('Libro Diario'!$E$10:$E$5000=1202001)*(YEAR('Libro Diario'!$C$10:$C$5000)=$D$5)*('Libro Diario'!$H$10:$H$5000))-SUMPRODUCT(('Libro Diario'!$A$10:$A$5000=$B$5)*('Libro Diario'!$E$10:$E$5000=1202001)*(YEAR('Libro Diario'!$C$10:$C$5000)=$D$5)*('Libro Diario'!$I$10:$I$5000)) -> 0
A43: Tractores (Bruto) | C43: Sec. 17 NIIF Pymes | D43: =SUMPRODUCT(('Libro Diario'!$A$10:$A$5000=$B$5)*('Libro Diario'!$E$10:$E$5000=1202003)*(YEAR('Libro Diario'!$C$10:$C$5000)=$D$5)*('Libro Diario'!$H$10:$H$5000))-SUMPRODUCT(('Libro Diario'!$A$10:$A$5000=$B$5)*('Libro Diario'!$E$10:$E$5000=1202003)*(YEAR('Libro Diario'!$C$10:$C$5000)=$D$5)*('Libro Diario'!$I$10:$I$5000)) -> 0
